Workbook

Sheet July 2023
A2: FOR THE MONTH OF JULY 2023
A4: Date | B4: KWH REPORT FIBER BLEACHING
B6: BUSWAY 1 (PRE AND POST BLOW ROOM + DRYER +BLEACHING MACHINES+ STAMP PRESS+ CAKE OPENOR+ CENTRIFUGE+ BALE PRESS) | E6: BUSWAY 2 | H6: MCC 1 (EXHAUST FAN+ FA FAN+ DRYER FAN+ SUBMERSIBLE PUMP +RECYCLE PUMP) | K6: MCC 2 (FA FAN +EXHAUST FAN CHEMICAL AREA+CAUSTIC FEED PUMP+WASTE WATER PUMP) | N6: MCC 3 (COMPRESSOR +FA FAN+ EXHAUST FAN)+BOILER | Q6: MCC 4 (SOFTENING PUMP+UV PUMP+FEED PUMP+ CAUSTIC PUMP+RAW WATER PUMP+ CHEMICAL AREA) | T6: MCC 5 (BOILER) | W6: LPDB 1 (PHASE 1 AND 2 LIGHTENING LOAD) | Z6: LPDB 2 (PRE BLOW ROOM LIGHTENING LOAD)
B7: Opening | C7: Closing | D7: Total Units Kwh / d | E7: Opening | F7: Closing | G7: Total Units Kwh / d | H7: Opening | I7: Closing | J7: Total Units Kwh / d | K7: Opening | L7: Closing | M7: Total Units Kwh / d | N7: Opening | O7: Closing | P7: Total Units Kwh / d | Q7: Opening | R7: Closing | S7: Total Units Kwh / d | T7: Opening | U7: Closing | V7: Total Units Kwh / d | W7: Opening | X7: Closing | Y7: Total Units Kwh / d | Z7: Opening | AA7: Closing | AB7: Total Units Kwh / d | AC7: TOTAL CONSUMED | AD7: MAIN INCOMING | AG7: Dif b/t main LT and consum
AD8: Opening | AE8: Closing | AF8: Total Units Kwh / d
A9: 45108 | B9: 613296.38 | C9: 613643.35 | D9: =SUM(C9-B9) -> 346.97 | E9: - | F9: - | G9: - | H9: 173578.72 | I9: 173786.48 | J9: =SUM(I9-H9) -> 207.76 | K9: 63693.88 | L9: 63761.48 | M9: =SUM(L9-K9) -> 67.6 | N9: 112042.48 | O9: 112361.52 | P9: =SUM(O9-N9-V9) -> 192.4 | Q9: 89160.49 | R9: 89728.64 | S9: =SUM(R9-Q9) -> 568.15 | T9: 12621.92 | U9: 12748.56 | V9: =SUM(U9-T9) -> 126.64 | W9: 48844.77 | X9: 48919.3 | Y9: =SUM(X9-W9) -> 74.53 | Z9: 27625.05 | AA9: 27642.16 | AB9: =SUM(AA9-Z9) -> 17.11 | AC9: =SUM(AB9+Y9+V9+S9+P9+M9+J9+D9) -> 1601.16 | AD9: 1154257.6 | AE9: 1156792.2 | AF9: =SUM(AE9-AD9) -> 2534.62 | AG9: =SUM(AF9-AC9) -> 933.46
A10: 45109 | B10: 613643.35 | C10: 614289.31 | D10: =SUM(C10-B10) -> 645.96 | H10: 173786.48 | I10: 173996.8 | J10: =SUM(I10-H10) -> 210.32 | K10: 63761.48 | L10: 63835.56 | M10: =SUM(L10-K10) -> 74.08 | N10: 112361.52 | O10: 112705.84 | P10: =SUM(O10-N10-V10) -> 227.12 | Q10: 89728.64 | R10: 89897.44 | S10: =SUM(R10-Q10) -> 168.8 | T10: 12748.56 | U10: 12865.76 | V10: =SUM(U10-T10) -> 117.2 | W10: 48919.3 | X10: 48972.69 | Y10: =SUM(X10-W10) -> 53.39 | Z10: 27642.16 | AA10: 27660.49 | AB10: =SUM(AA10-Z10) -> 18.33 | AC10: =SUM(AB10+Y10+V10+S10+P10+M10+J10+D10) -> 1515.2 | AD10: 1156792.2 | AE10: 1158484 | AF10: =SUM(AE10-AD10) -> 1691.82 | AG10: =SUM(AF10-AC10) -> 176.62
A11: 45110 | B11: 614289.31 | C11: 615104.28 | D11: =SUM(C11-B11) -> 814.97 | H11: 173996.8 | I11: 174217.2 | J11: =SUM(I11-H11) -> 220.4 | K11: 63835.56 | L11: 63972.08 | M11: =SUM(L11-K11) -> 136.52 | N11: 112705.84 | O11: 112993.04 | P11: =SUM(O11-N11-V11) -> 200.36 | Q11: 89897.44 | R11: 90059.12 | S11: =SUM(R11-Q11) -> 161.68 | T11: 12865.76 | U11: 12952.6 | V11: =SUM(U11-T11) -> 86.84 | W11: 48972.69 | X11: 49070.19 | Y11: =SUM(X11-W11) -> 97.5 | Z11: 27660.49 | AA11: 27688.87 | AB11: =SUM(AA11-Z11) -> 28.38 | AC11: =SUM(AB11+Y11+V11+S11+P11+M11+J11+D11) -> 1746.65 | AD11: 1158484 | AE11: 1160565.1 | AF11: =SUM(AE11-AD11) -> 2081.04 | AG11: =SUM(AF11-AC11) -> 334.39
A12: 45111 | B12: 615104.28 | C12: 620114.96 | D12: =SUM(C12-B12) -> 5010.68 | H12: 174217.2 | I12: 175253.68 | J12: =SUM(I12-H12) -> 1036.48 | K12: 63972.08 | L12: 64312.92 | M12: =SUM(L12-K12) -> 340.84 | N12: 112993.04 | O12: 113774.4 | P12: =SUM(O12-N12-V12) -> 539.04 | Q12: 90059.12 | R12: 90527.36 | S12: =SUM(R12-Q12) -> 468.24 | T12: 12952.6 | U12: 13194.92 | V12: =SUM(U12-T12) -> 242.32 | W12: 49070.19 | X12: 49249.46 | Y12: =SUM(X12-W12) -> 179.27 | Z12: 27688.87 | AA12: 27786.28 | AB12: =SUM(AA12-Z12) -> 97.41 | AC12: =SUM(AB12+Y12+V12+S12+P12+M12+J12+D12) -> 7914.28 | AD12: 1160565.1 | AE12: 1168896.8 | AF12: =SUM(AE12-AD12) -> 8331.71 | AG12: =SUM(AF12-AC12) -> 417.43
A13: 45112 | B13: 620114.96 | C13: 624548.84 | D13: =SUM(C13-B13) -> 4433.88 | H13: 175253.68 | I13: 176289.52 | J13: =SUM(I13-H13) -> 1035.84 | K13: 64312.92 | L13: 64685 | M13: =SUM(L13-K13) -> 372.08 | N13: 113774.4 | O13: 114559.52 | P13: =SUM(O13-N13-V13) -> 531.88 | Q13: 90527.36 | R13: 90941.36 | S13: =SUM(R13-Q13) -> 414 | T13: 13194.92 | U13: 13448.16 | V13: =SUM(U13-T13) -> 253.24 | W13: 49249.46 | X13: 49388.22 | Y13: =SUM(X13-W13) -> 138.76 | Z13: 27786.28 | AA13: 27865.83 | AB13: =SUM(AA13-Z13) -> 79.55 | AC13: =SUM(AB13+Y13+V13+S13+P13+M13+J13+D13) -> 7259.23 | AD13: 1168896.8 | AE13: 1176593.1 | AF13: =SUM(AE13-AD13) -> 7696.31 | AG13: =SUM(AF13-AC13) -> 437.08
A14: 45113 | B14: 624548.84 | C14: =B15 -> 628998.6 | D14: =SUM(C14-B14) -> 4449.76 | H14: 176289.52 | I14: =H15 -> 177443.76 | J14: =SUM(I14-H14) -> 1154.24 | K14: 64685 | L14: =K15 -> 64994.2 | M14: =SUM(L14-K14) -> 309.2 | N14: 114559.52 | O14: =N15 -> 115312.56 | P14: =SUM(O14-N14-V14) -> 510.36 | Q14: 90941.36 | R14: =Q15 -> 91369.84 | S14: =SUM(R14-Q14) -> 428.48 | T14: 13448.16 | U14: =T15 -> 13690.84 | V14: =SUM(U14-T14) -> 242.68 | W14: 49388.22 | X14: =W15 -> 49559.5 | Y14: =SUM(X14-W14) -> 171.28 | Z14: 27865.83 | AA14: =Z15 -> 27947.5 | AB14: =SUM(AA14-Z14) -> 81.67 | AC14: =SUM(AB14+Y14+V14+S14+P14+M14+J14+D14) -> 7347.67 | AD14: 1176593.1 | AE14: =AD15 -> 1184321.6 | AF14: =SUM(AE14-AD14) -> 7728.5 | AG14: =SUM(AF14-AC14) -> 380.83
A15: 45114 | B15: 628998.6 | C15: =B16 -> 633206.17 | D15: =SUM(C15-B15) -> 4207.57 | H15: 177443.76 | I15: =H16 -> 178923.2 | J15: =SUM(I15-H15) -> 1479.44 | K15: 64994.2 | L15: =K16 -> 65846.84 | M15: =SUM(L15-K15) -> 852.64 | N15: 115312.56 | O15: =N16 -> 116099.6 | P15: =SUM(O15-N15-V15) -> 526.76 | Q15: 91369.84 | R15: =Q16 -> 91812.08 | S15: =SUM(R15-Q15) -> 442.24 | T15: 13690.84 | U15: =T16 -> 13951.12 | V15: =SUM(U15-T15) -> 260.28 | W15: 49559.5 | X15: =W16 -> 49728.12 | Y15: =SUM(X15-W15) -> 168.62 | Z15: 27947.5 | AA15: =Z16 -> 28007.67 | AB15: =SUM(AA15-Z15) -> 60.17 | AC15: =SUM(AB15+Y15+V15+S15+P15+M15+J15+D15) -> 7997.72 | AD15: 1184321.6 | AE15: =AD16 -> 1192757.6 | AF15: =SUM(AE15-AD15) -> 8435.96 | AG15: =SUM(AF15-AC15) -> 438.24
A16: 45115 | B16: 633206.17 | C16: 635911.4 | D16: =SUM(C16-B16) -> 2705.23 | H16: 178923.2 | I16: 180357.92 | J16: =SUM(I16-H16) -> 1434.72 | K16: 65846.84 | L16: 66530.8 | M16: =SUM(L16-K16) -> 683.96 | N16: 116099.6 | O16: 116792.88 | P16: =SUM(O16-N16-V16) -> 454.68 | Q16: 91812.08 | R16: 92464.4 | S16: =SUM(R16-Q16) -> 652.32 | T16: 13951.12 | U16: 14189.72 | V16: =SUM(U16-T16) -> 238.6 | W16: 49728.12 | X16: 49881.3 | Y16: =SUM(X16-W16) -> 153.18 | Z16: 28007.67 | AA16: 28079.86 | AB16: =SUM(AA16-Z16) -> 72.19 | AC16: =SUM(AB16+Y16+V16+S16+P16+M16+J16+D16) -> 6394.88 | AD16: 1192757.6 | AE16: 1199513.5 | AF16: =SUM(AE16-AD16) -> 6755.94 | AG16: =SUM(AF16-AC16) -> 361.06
A17: 45116 | B17: =C16 -> 635911.4 | C17: 639148.06 | D17: =SUM(C17-B17) -> 3236.66 | H17: =I16 -> 180357.92 | I17: 181173.36 | J17: =SUM(I17-H17) -> 815.44 | K17: =L16 -> 66530.8 | L17: 66887 | M17: =SUM(L17-K17) -> 356.2 | N17: =O16 -> 116792.88 | O17: 117284.16 | P17: =SUM(O17-N17-V17) -> 327.48 | Q17: =R16 -> 92464.4 | R17: 92978.56 | S17: =SUM(R17-Q17) -> 514.16 | T17: =U16 -> 14189.72 | U17: 14353.52 | V17: =SUM(U17-T17) -> 163.8 | W17: =X16 -> 49881.3 | X17: 49963.27 | Y17: =SUM(X17-W17) -> 81.97 | Z17: =AA16 -> 28079.86 | AA17: 28121.52 | AB17: =SUM(AA17-Z17) -> 41.66 | AC17: =SUM(AB17+Y17+V17+S17+P17+M17+J17+D17) -> 5537.37 | AD17: =AE16 -> 1199513.5 | AE17: 1205302 | AF17: =SUM(AE17-AD17) -> 5788.46 | AG17: =SUM(AF17-AC17) -> 251.09
A18: 45117 | B18: =C17 -> 639148.06 | C18: 641820.42 | D18: =SUM(C18-B18) -> 2672.36 | H18: =I17 -> 181173.36 | I18: 181926.64 | J18: =SUM(I18-H18) -> 753.28 | K18: =L17 -> 66887 | L18: 67654.24 | M18: =SUM(L18-K18) -> 767.24 | N18: =O17 -> 117284.16 | O18: 117807 | P18: =SUM(O18-N18-V18) -> 330.44 | Q18: =R17 -> 92978.56 | R18: 93284.4 | S18: =SUM(R18-Q18) -> 305.84 | T18: =U17 -> 14353.52 | U18: 14545.92 | V18: =SUM(U18-T18) -> 192.4 | W18: =X17 -> 49963.27 | X18: 50097.6 | Y18: =SUM(X18-W18) -> 134.33 | Z18: =AA17 -> 28121.52 | AA18: 28168.53 | AB18: =SUM(AA18-Z18) -> 47.01 | AC18: =SUM(AB18+Y18+V18+S18+P18+M18+J18+D18) -> 5202.9 | AD18: =AE17 -> 1205302 | AE18: 1210838.6 | AF18: =SUM(AE18-AD18) -> 5536.59 | AG18: =SUM(AF18-AC18) -> 333.69
A19: 45118 | B19: =C18 -> 641820.42 | C19: 644512.22 | D19: =SUM(C19-B19) -> 2691.8 | H19: =I18 -> 181926.64 | I19: 182748.48 | J19: =SUM(I19-H19) -> 821.84 | K19: =L18 -> 67654.24 | L19: 67960.76 | M19: =SUM(L19-K19) -> 306.52 | N19: =O18 -> 117807 | O19: 118326.96 | P19: =SUM(O19-N19-V19) -> 318.68 | Q19: =R18 -> 93284.4 | R19: 93645.76 | S19: =SUM(R19-Q19) -> 361.36 | T19: =U18 -> 14545.92 | U19: 14747.2 | V19: =SUM(U19-T19) -> 201.28 | W19: =X18 -> 50097.6 | X19: 50216.84 | Y19: =SUM(X19-W19) -> 119.24 | Z19: =AA18 -> 28168.53 | AA19: 28205.04 | AB19: =SUM(AA19-Z19) -> 36.51 | AC19: =SUM(AB19+Y19+V19+S19+P19+M19+J19+D19) -> 4857.23 | AD19: =AE18 -> 1210838.6 | AE19: 1216007.5 | AF19: =SUM(AE19-AD19) -> 5168.95 | AG19: =SUM(AF19-AC19) -> 311.72
A20: 45119 | B20: =C19 -> 644512.22 | C20: 647237.86 | D20: =SUM(C20-B20) -> 2725.64 | H20: =I19 -> 182748.48 | I20: 183407.12 | J20: =SUM(I20-H20) -> 658.64 | K20: =L19 -> 67960.76 | L20: 68129.36 | M20: =SUM(L20-K20) -> 168.6 | N20: =O19 -> 118326.96 | O20: 118831.12 | P20: =SUM(O20-N20-V20) -> 319.44 | Q20: =R19 -> 93645.76 | R20: 93981.84 | S20: =SUM(R20-Q20) -> 336.08 | T20: =U19 -> 14747.2 | U20: 14931.92 | V20: =SUM(U20-T20) -> 184.72 | W20: =X19 -> 50216.84 | X20: 50339.32 | Y20: =SUM(X20-W20) -> 122.48 | Z20: =AA19 -> 28205.04 | AA20: 28254.5 | AB20: =SUM(AA20-Z20) -> 49.46 | AC20: =SUM(AB20+Y20+V20+S20+P20+M20+J20+D20) -> 4565.06 | AD20: =AE19 -> 1216007.5 | AE20: 1220894.5 | AF20: =SUM(AE20-AD20) -> 4887 | AG20: =SUM(AF20-AC20) -> 321.94
A21: 45120 | B21: =C20 -> 647237.86 | C21: =B22 -> 650164.43 | D21: =SUM(C21-B21) -> 2926.57 | H21: =I20 -> 183407.12 | I21: =H22 -> 184106 | J21: =SUM(I21-H21) -> 698.88 | K21: =L20 -> 68129.36 | L21: =K22 -> 68591.64 | M21: =SUM(L21-K21) -> 462.28 | N21: =O20 -> 118831.12 | O21: =N22 -> 119350.4 | P21: =SUM(O21-N21-V21) -> 335.28 | Q21: =R20 -> 93981.84 | R21: =Q22 -> 94352.72 | S21: =SUM(R21-Q21) -> 370.88 | T21: =U20 -> 14931.92 | U21: =T22 -> 15115.92 | V21: =SUM(U21-T21) -> 184 | W21: =X20 -> 50339.32 | X21: =W22 -> 50479.46 | Y21: =SUM(X21-W21) -> 140.14 | Z21: =AA20 -> 28254.5 | AA21: =Z22 -> 28298.65 | AB21: =SUM(AA21-Z21) -> 44.15 | AC21: =SUM(AB21+Y21+V21+S21+P21+M21+J21+D21) -> 5162.18 | AD21: =AE20 -> 1220894.5 | AE21: =AD22 -> 1226379.1 | AF21: =SUM(AE21-AD21) -> 5484.63 | AG21: =SUM(AF21-AC21) -> 322.45
A22: 45121 | B22: 650164.43 | C22: 653071.13 | D22: =SUM(C22-B22) -> 2906.7 | H22: 184106 | I22: 184835.68 | J22: =SUM(I22-H22) -> 729.68 | K22: 68591.64 | L22: 69279.08 | M22: =SUM(L22-K22) -> 687.44 | N22: 119350.4 | O22: 119930.16 | P22: =SUM(O22-N22-V22) -> 391.32 | Q22: 94352.72 | R22: 94748.32 | S22: =SUM(R22-Q22) -> 395.6 | T22: 15115.92 | U22: 15304.36 | V22: =SUM(U22-T22) -> 188.44 | W22: 50479.46 | X22: 50603.2 | Y22: =SUM(X22-W22) -> 123.74 | Z22: 28298.65 | AA22: 28338.21 | AB22: =SUM(AA22-Z22) -> 39.56 | AC22: =SUM(AB22+Y22+V22+S22+P22+M22+J22+D22) -> 5462.48 | AD22: 1226379.1 | AE22: 1232165.9 | AF22: =SUM(AE22-AD22) -> 5786.82 | AG22: =SUM(AF22-AC22) -> 324.34
A23: 45122 | B23: =C22 -> 653071.13 | C23: 656326.76 | D23: =SUM(C23-B23) -> 3255.63 | H23: =I22 -> 184835.68 | I23: 185556.64 | J23: =SUM(I23-H23) -> 720.96 | K23: =L22 -> 69279.08 | L23: 69750.28 | M23: =SUM(L23-K23) -> 471.2 | N23: =O22 -> 119930.16 | O23: 120500.24 | P23: =SUM(O23-N23-V23) -> 393 | Q23: =R22 -> 94748.32 | R23: 95157.28 | S23: =SUM(R23-Q23) -> 408.96 | T23: =U22 -> 15304.36 | U23: 15481.44 | V23: =SUM(U23-T23) -> 177.08 | W23: =X22 -> 50603.2 | X23: 50718.34 | Y23: =SUM(X23-W23) -> 115.14 | Z23: =AA22 -> 28338.21 | AA23: 28405.42 | AB23: =SUM(AA23-Z23) -> 67.21 | AC23: =SUM(AB23+Y23+V23+S23+P23+M23+J23+D23) -> 5609.18 | AD23: =AE22 -> 1232165.9 | AE23: 1238087.9 | AF23: =SUM(AE23-AD23) -> 5921.93 | AG23: =SUM(AF23-AC23) -> 312.75
A24: 45123 | B24: =C23 -> 656326.76 | C24: 659391.7 | D24: =SUM(C24-B24) -> 3064.94 | H24: =I23 -> 185556.64 | I24: 186207.84 | J24: =SUM(I24-H24) -> 651.2 | K24: =L23 -> 69750.28 | L24: 69972.24 | M24: =SUM(L24-K24) -> 221.96 | N24: =O23 -> 120500.24 | O24: 121065.76 | P24: =SUM(O24-N24-V24) -> 392.68 | Q24: =R23 -> 95157.28 | R24: 95526.16 | S24: =SUM(R24-Q24) -> 368.88 | T24: =U23 -> 15481.44 | U24: 15654.28 | V24: =SUM(U24-T24) -> 172.84 | W24: =X23 -> 50718.34 | X24: 50862.58 | Y24: =SUM(X24-W24) -> 144.24 | Z24: =AA23 -> 28405.42 | AA24: 28463 | AB24: =SUM(AA24-Z24) -> 57.58 | AC24: =SUM(AB24+Y24+V24+S24+P24+M24+J24+D24) -> 5074.32 | AD24: =AE23 -> 1238087.9 | AE24: 1243406.5 | AF24: =SUM(AE24-AD24) -> 5318.62 | AG24: =SUM(AF24-AC24) -> 244.3
A25: 45124 | B25: =C24 -> 659391.7 | C25: 662588.88 | D25: =SUM(C25-B25) -> 3197.18 | H25: =I24 -> 186207.84 | I25: 186889.88 | J25: =SUM(I25-H25) -> 682.04 | K25: =L24 -> 69972.24 | L25: 70249.8 | M25: =SUM(L25-K25) -> 277.56 | N25: =O24 -> 121065.76 | O25: 121642.16 | P25: =SUM(O25-N25-V25) -> 395.96 | Q25: =R24 -> 95526.16 | R25: 95905.6 | S25: =SUM(R25-Q25) -> 379.44 | T25: =U24 -> 15654.28 | U25: 15834.72 | V25: =SUM(U25-T25) -> 180.44 | W25: =X24 -> 50862.58 | X25: 50997.26 | Y25: =SUM(X25-W25) -> 134.68 | Z25: =AA24 -> 28463 | AA25: 28543.84 | AB25: =SUM(AA25-Z25) -> 80.84 | AC25: =SUM(AB25+Y25+V25+S25+P25+M25+J25+D25) -> 5328.14 | AD25: =AE24 -> 1243406.5 | AE25: 1249057.2 | AF25: =SUM(AE25-AD25) -> 5650.72 | AG25: =SUM(AF25-AC25) -> 322.58
A26: 45125 | B26: =C25 -> 662588.88 | C26: 664405.6 | D26: =SUM(C26-B26) -> 1816.72 | H26: =I25 -> 186889.88 | I26: 187777.12 | J26: =SUM(I26-H26) -> 887.24 | K26: =L25 -> 70249.8 | L26: 70407.92 | M26: =SUM(L26-K26) -> 158.12 | N26: =O25 -> 121642.16 | O26: 122181.2 | P26: =SUM(O26-N26-V26) -> 352.52 | Q26: =R25 -> 95905.6 | R26: 96172.48 | S26: =SUM(R26-Q26) -> 266.88 | T26: =U25 -> 15834.72 | U26: 16021.24 | V26: =SUM(U26-T26) -> 186.52 | W26: =X25 -> 50997.26 | X26: 51153.58 | Y26: =SUM(X26-W26) -> 156.32 | Z26: =AA25 -> 28543.84 | AA26: 28616.63 | AB26: =SUM(AA26-Z26) -> 72.79 | AC26: =SUM(AB26+Y26+V26+S26+P26+M26+J26+D26) -> 3897.11 | AD26: =AE25 -> 1249057.2 | AE26: 1253303.2 | AF26: =SUM(AE26-AD26) -> 4245.98 | AG26: =SUM(AF26-AC26) -> 348.87
A27: 45126 | B27: =C26 -> 664405.6 | C27: 667269.9 | D27: =SUM(C27-B27) -> 2864.3 | H27: =I26 -> 187777.12 | I27: 188745.84 | J27: =SUM(I27-H27) -> 968.72 | K27: =L26 -> 70407.92 | L27: 70681.4 | M27: =SUM(L27-K27) -> 273.48 | N27: =O26 -> 122181.2 | O27: 122745.2 | P27: =SUM(O27-N27-V27) -> 380.56 | Q27: =R26 -> 96172.48 | R27: 96535.4 | S27: =SUM(R27-Q27) -> 362.92 | T27: =U26 -> 16021.24 | U27: 16204.68 | V27: =SUM(U27-T27) -> 183.44 | W27: =X26 -> 51153.58 | X27: 51348.1 | Y27: =SUM(X27-W27) -> 194.52 | Z27: =AA26 -> 28616.63 | AA27: 28734.34 | AB27: =SUM(AA27-Z27) -> 117.71 | AC27: =SUM(AB27+Y27+V27+S27+P27+M27+J27+D27) -> 5345.65 | AD27: =AE26 -> 1253303.2 | AE27: 1258996.5 | AF27: =SUM(AE27-AD27) -> 5693.3 | AG27: =SUM(AF27-AC27) -> 347.65
A28: 45127 | B28: =C27 -> 667269.9 | C28: 670159.95 | D28: =SUM(C28-B28) -> 2890.05 | H28: =I27 -> 188745.84 | I28: =H29 -> 189701.72 | J28: =SUM(I28-H28) -> 955.88 | K28: =L27 -> 70681.4 | L28: =K29 -> 70912.84 | M28: =SUM(L28-K28) -> 231.44 | N28: =O27 -> 122745.2 | O28: =N29 -> 123324.08 | P28: =SUM(O28-N28-V28) -> 382.84 | Q28: =R27 -> 96535.4 | R28: =Q29 -> 96901.52 | S28: =SUM(R28-Q28) -> 366.12 | T28: =U27 -> 16204.68 | U28: =T29 -> 16400.72 | V28: =SUM(U28-T28) -> 196.04 | W28: =X27 -> 51348.1 | X28: =W29 -> 51505.11 | Y28: =SUM(X28-W28) -> 157.01 | Z28: =AA27 -> 28734.34 | AA28: =Z29 -> 28816.81 | AB28: =SUM(AA28-Z28) -> 82.47 | AC28: =SUM(AB28+Y28+V28+S28+P28+M28+J28+D28) -> 5261.85 | AD28: =AE27 -> 1258996.5 | AE28: =AD29 -> 1264578.6 | AF28: =SUM(AE28-AD28) -> 5582.05 | AG28: =SUM(AF28-AC28) -> 320.2
A29: 45128 | B29: 670160 | C29: =B30 -> 673253.5 | D29: =SUM(C29-B29) -> 3093.5 | H29: 189701.72 | I29: =H30 -> 190747.52 | J29: =SUM(I29-H29) -> 1045.8 | K29: 70912.84 | L29: =K30 -> 71177.48 | M29: =SUM(L29-K29) -> 264.64 | N29: 123324.08 | O29: =N30 -> 123897.36 | P29: =SUM(O29-N29-V29) -> 390.63 | Q29: 96901.52 | R29: =Q30 -> 97314 | S29: =SUM(R29-Q29) -> 412.48 | T29: 16400.72 | U29: =T30 -> 16583.37 | V29: =SUM(U29-T29) -> 182.65 | W29: 51505.11 | X29: =W30 -> 51692.38 | Y29: =SUM(X29-W29) -> 187.27 | Z29: 28816.81 | AA29: =Z30 -> 28879.95 | AB29: =SUM(AA29-Z29) -> 63.14 | AC29: =SUM(AB29+Y29+V29+S29+P29+M29+J29+D29) -> 5640.11 | AD29: 1264578.6 | AE29: =AD30 -> 1270610.8 | AF29: =SUM(AE29-AD29) -> 6032.2 | AG29: =SUM(AF29-AC29) -> 392.09
A30: 45129 | B30: 673253.5 | C30: 676449.2 | D30: =SUM(C30-B30) -> 3195.7 | H30: 190747.52 | I30: 191861.92 | J30: =SUM(I30-H30) -> 1114.4 | K30: 71177.48 | L30: 71574.72 | M30: =SUM(L30-K30) -> 397.24 | N30: 123897.36 | O30: 124505.84 | P30: =SUM(O30-N30-V30) -> 408.99 | Q30: 97314 | R30: 97759.2 | S30: =SUM(R30-Q30) -> 445.2 | T30: 16583.37 | U30: 16782.86 | V30: =SUM(U30-T30) -> 199.49 | W30: 51692.38 | X30: 51842.73 | Y30: =SUM(X30-W30) -> 150.35 | Z30: 28879.95 | AA30: 28952.02 | AB30: =SUM(AA30-Z30) -> 72.07 | AC30: =SUM(AB30+Y30+V30+S30+P30+M30+J30+D30) -> 5983.44 | AD30: 1270610.8 | AE30: 1276949.2 | AF30: =SUM(AE30-AD30) -> 6338.44 | AG30: =SUM(AF30-AC30) -> 355
A31: 45130 | B31: =C30 -> 676449.2 | C31: 679713.43 | D31: =SUM(C31-B31) -> 3264.23 | H31: =I30 -> 191861.92 | I31: 193010.8 | J31: =SUM(I31-H31) -> 1148.88 | K31: =L30 -> 71574.72 | L31: 71859.84 | M31: =SUM(L31-K31) -> 285.12 | N31: =O30 -> 124505.84 | O31: 125094.24 | P31: =SUM(O31-N31-V31) -> 425.26 | Q31: =R30 -> 97759.2 | R31: 98222.72 | S31: =SUM(R31-Q31) -> 463.52 | T31: =U30 -> 16782.86 | U31: 16946 | V31: =SUM(U31-T31) -> 163.14 | W31: =X30 -> 51842.73 | X31: 52021.89 | Y31: =SUM(X31-W31) -> 179.16 | Z31: =AA30 -> 28952.02 | AA31: 29009.41 | AB31: =SUM(AA31-Z31) -> 57.39 | AC31: =SUM(AB31+Y31+V31+S31+P31+M31+J31+D31) -> 5986.7 | AD31: =AE30 -> 1276949.2 | AE31: 1283202.9 | AF31: =SUM(AE31-AD31) -> 6253.66 | AG31: =SUM(AF31-AC31) -> 266.96
A32: 45131 | B32: =C31 -> 679713.43 | C32: 682260.96 | D32: =SUM(C32-B32) -> 2547.53 | H32: =I31 -> 193010.8 | I32: =H33 -> 193786.32 | J32: =SUM(I32-H32) -> 775.52 | K32: =L31 -> 71859.84 | L32: 72189 | M32: =SUM(L32-K32) -> 329.16 | N32: =O31 -> 125094.24 | O32: 125647.6 | P32: =SUM(O32-N32-V32) -> 344.56 | Q32: =R31 -> 98222.72 | R32: =Q33 -> 98622.64 | S32: =SUM(R32-Q32) -> 399.92 | T32: =U31 -> 16946 | U32: =T33 -> 17154.8 | V32: =SUM(U32-T32) -> 208.8 | W32: =X31 -> 52021.89 | X32: =W33 -> 52144.65 | Y32: =SUM(X32-W32) -> 122.76 | Z32: =AA31 -> 29009.41 | AA32: =Z33 -> 29067 | AB32: =SUM(AA32-Z32) -> 57.59 | AC32: =SUM(AB32+Y32+V32+S32+P32+M32+J32+D32) -> 4785.84 | AD32: =AE31 -> 1283202.9 | AE32: =AD33 -> 1288274.2 | AF32: =SUM(AE32-AD32) -> 5071.35 | AG32: =SUM(AF32-AC32) -> 285.51
A33: 45132 | B33: =C32 -> 682260.96 | C33: 684449.01 | D33: =SUM(C33-B33) -> 2188.05 | E33: - | F33: - | G33: - | H33: 193786.32 | I33: 194535.28 | J33: =SUM(I33-H33) -> 748.96 | K33: 72189.72 | L33: =K34 -> 72363.363 | M33: =SUM(L33-K33) -> 173.643 | N33: 125647.6 | O33: 126071.76 | P33: =SUM(O33-N33-V33) -> 274.56 | Q33: 98622.64 | R33: =Q34 -> 98818.8 | S33: =SUM(R33-Q33) -> 196.16 | T33: 17154.8 | U33: =T34 -> 17304.4 | V33: =SUM(U33-T33) -> 149.6 | W33: 52144.65 | X33: =W34 -> 52263.74 | Y33: =SUM(X33-W33) -> 119.09 | Z33: 29067 | AA33: =Z34 -> 29114.44 | AB33: =SUM(AA33-Z33) -> 47.44 | AC33: =SUM(AB33+Y33+V33+S33+P33+M33+J33+D33) -> 3897.503 | AD33: 1288274.2 | AE33: =AD34 -> 1292485.8 | AF33: =SUM(AE33-AD33) -> 4211.63 | AG33: =SUM(AF33-AC33) -> 314.127
A34: 45133 | B34: 684449.01 | C34: =B35 -> 686402.13 | D34: =SUM(C34-B34) -> 1953.12 | H34: =I33 -> 194535.28 | I34: =H35 -> 195612.1 | J34: =SUM(I34-H34) -> 1076.82 | K34: 72363.363 | L34: =K35 -> 72553.96 | M34: =SUM(L34-K34) -> 190.597 | N34: 126071.76 | O34: =N35 -> 126556.96 | P34: =SUM(O34-N34-V34) -> 298.36 | Q34: 98818.8 | R34: =Q35 -> 99147.6 | S34: =SUM(R34-Q34) -> 328.8 | T34: 17304.4 | U34: =T35 -> 17491.24 | V34: =SUM(U34-T34) -> 186.84 | W34: 52263.74 | X34: =W35 -> 52445.41 | Y34: =SUM(X34-W34) -> 181.67 | Z34: 29114.44 | AA34: =Z35 -> 29173.84 | AB34: =SUM(AA34-Z34) -> 59.4 | AC34: =SUM(AB34+Y34+V34+S34+P34+M34+J34+D34) -> 4275.607 | AD34: 1292485.8 | AE34: =AD35 -> 1297073.5 | AF34: =SUM(AE34-AD34) -> 4587.64 | AG34: =SUM(AF34-AC34) -> 312.033
A35: 45134 | B35: 686402.13 | C35: 686469.33 | D35: =SUM(C35-B35) -> 67.2 | H35: 195612.1 | I35: 195789.24 | J35: =SUM(I35-H35) -> 177.14 | K35: 72553.96 | L35: 72637.24 | M35: =SUM(L35-K35) -> 83.28 | N35: 126556.96 | O35: 126784 | P35: =SUM(O35-N35-V35) -> 150.52 | Q35: 99147.6 | R35: 99469.84 | S35: =SUM(R35-Q35) -> 322.24 | T35: 17491.24 | U35: 17567.76 | V35: =SUM(U35-T35) -> 76.52 | W35: 52445.41 | X35: 52616.57 | Y35: =SUM(X35-W35) -> 171.16 | Z35: 29173.84 | AA35: 29257.05 | AB35: =SUM(AA35-Z35) -> 83.21 | AC35: =SUM(AB35+Y35+V35+S35+P35+M35+J35+D35) -> 1131.27 | AD35: 1297073.5 | AE35: 1298622.5 | AF35: =SUM(AE35-AD35) -> 1549.04 | AG35: =SUM(AF35-AC35) -> 417.77
A36: 45135 | C36: =B37 -> 0 | D36: =SUM(C36-B36) -> 0 | I36: =H37 -> 0 | J36: =SUM(I36-H36) -> 0 | L36: =K37 -> 0 | M36: =SUM(L36-K36) -> 0 | O36: =N37 -> 0 | P36: =SUM(O36-N36-V36) -> 0 | R36: =Q37 -> 0 | S36: =SUM(R36-Q36) -> 0 | U36: =T37 -> 0 | V36: =SUM(U36-T36) -> 0 | X36: =W37 -> 0 | Y36: =SUM(X36-W36) -> 0 | AA36: =Z37 -> 0 | AB36: =SUM(AA36-Z36) -> 0 | AC36: =SUM(AB36+Y36+V36+S36+P36+M36+J36+D36) -> 0 | AE36: =AD37 -> 0 | AF36: =SUM(AE36-AD36) -> 0 | AG36: =SUM(AF36-AC36) -> 0
A37: 45136 | D37: =SUM(C37-B37) -> 0 | J37: =SUM(I37-H37) -> 0 | M37: =SUM(L37-K37) -> 0 | S37: =SUM(R37-Q37) -> 0 | V37: =SUM(U37-T37) -> 0 | Y37: =SUM(X37-W37) -> 0 | AB37: =SUM(AA37-Z37) -> 0 | AC37: =SUM(AB37+Y37+V37+S37+P37+M37+J37+D37) -> 0 | AE37: =AD38 -> 1298622.5 | AF37: =SUM(AE37-AD37) -> 1298622.5 | AG37: =SUM(AF37-AC37) -> 1298622.5
A38: 45137 | B38: =C35 -> 686469.33 | C38: =B39 -> 686469.3 | D38: 0 | H38: 195798.24 | I38: 195884.32 | J38: =SUM(I38-H38) -> 86.08 | K38: =L35 -> 72637.24 | L38: =K39 -> 72676.72 | M38: =SUM(L38-K38) -> 39.48 | N38: =O35 -> 126784 | O38: 126831.76 | P38: =SUM(O38-N38-V38) -> 29.2 | Q38: =R35 -> 99469.84 | R38: =Q39 -> 99569.6 | S38: =SUM(R38-Q38) -> 99.76 | T38: =U35 -> 17567.76 | U38: =T39 -> 17586.32 | V38: =SUM(U38-T38) -> 18.56 | W38: =X35 -> 52616.57 | X38: =W39 -> 52660.4 | Y38: =SUM(X38-W38) -> 43.83 | Z38: =AA35 -> 29257.05 | AA38: =Z39 -> 29276.1 | AB38: =SUM(AA38-Z38) -> 19.05 | AC38: =SUM(AB38+Y38+V38+S38+P38+M38+J38+D38) -> 335.96 | AD38: =AE35 -> 1298622.5 | AE38: =AD39 -> 1299110.3 | AF38: =SUM(AE38-AD38) -> 487.79 | AG38: =SUM(AF38-AC38) -> 151.83
A39: 45138 | B39: =686469.3 -> 686469.3 | C39: 687120.5 | D39: =SUM(C39-B39) -> 651.2 | H39: 195884.32 | I39: 196311.84 | J39: =SUM(I39-H39) -> 427.52 | K39: 72676.72 | L39: 72784.44 | M39: =SUM(L39-K39) -> 107.72 | N39: 126831.76 | O39: 127202.2 | P39: =SUM(O39-N39-V39) -> 229.24 | Q39: 99569.6 | R39: 99732.64 | S39: =SUM(R39-Q39) -> 163.04 | T39: 17586.32 | U39: 17727.52 | V39: =SUM(U39-T39) -> 141.2 | W39: 52660.4 | X39: 52800 | Y39: =SUM(X39-W39) -> 139.6 | Z39: 29276.1 | AA39: 29314.8 | AB39: =SUM(AA39-Z39) -> 38.7 | AC39: =SUM(AB39+Y39+V39+S39+P39+M39+J39+D39) -> 1898.22 | AD39: 1299110.3 | AE39: 1301320.2 | AF39: =SUM(AE39-AD39) -> 2209.9 | AG39: =SUM(AF39-AC39) -> 311.68
D40: =SUM(D8:D39) -> 73824.1 | J40: =SUM(J9:J39) -> 22724.12 | M40: =SUM(M9:M39) -> 9089.84 | P40: =SUM(P9:P39) -> 10054.12 | S40: =SUM(S9:S39) -> 10572.15 | V40: =SUM(V9:V39) -> 5105.6 | Y40: =SUM(Y9:Y39) -> 3955.23 | AB40: =SUM(AB9:AB39) -> 1689.75 | AF40: =SUM(AF9:AF39) -> 1445685.1

Sheet Aug 2023
A2: FOR THE MONTH OF AUGUST 2023
A4: Date | B4: KWH REPORT FIBER BLEACHING
B6: BUSWAY 1 (PRE AND POST BLOW ROOM + DRYER +BLEACHING MACHINES+ STAMP PRESS+ CAKE OPENOR+ CENTRIFUGE+ BALE PRESS) | E6: BUSWAY 2 | H6: MCC 1 (EXHAUST FAN+ FA FAN+ DRYER FAN+ SUBMERSIBLE PUMP +RECYCLE PUMP) | K6: MCC 2 (FA FAN +EXHAUST FAN CHEMICAL AREA+CAUSTIC FEED PUMP+WASTE WATER PUMP) | N6: MCC 3 (COMPRESSOR +FA FAN+ EXHAUST FAN)+BOILER | Q6: MCC 4 (SOFTENING PUMP+UV PUMP+FEED PUMP+ CAUSTIC PUMP+RAW WATER PUMP+ CHEMICAL AREA) | T6: MCC 5 (BOILER) | W6: LPDB 1 (PHASE 1 AND 2 LIGHTENING LOAD) | Z6: LPDB 2 (PRE BLOW ROOM LIGHTENING LOAD) | AC6: LPDB OFFICE
B7: Opening | C7: Closing | D7: Total Units Kwh / d | E7: Opening | F7: Closing | G7: Total Units Kwh / d | H7: Opening | I7: Closing | J7: Total Units Kwh / d | K7: Opening | L7: Closing | M7: Total Units Kwh / d | N7: Opening | O7: Closing | P7: Total Units Kwh / d | Q7: Opening | R7: Closing | S7: Total Units Kwh / d | T7: Opening | U7: Closing | V7: Total Units Kwh / d | W7: Opening | X7: Closing | Y7: Total Units Kwh / d | Z7: Opening | AA7: Closing | AB7: Total Units Kwh / d | AC7: Opening | AD7: Closing | AE7: Total Units Kwh / d | AF7: TOTAL CONSUMED | AG7: MAIN INCOMING | AJ7: Dif b/t main LT and consum
AG8: Opening | AH8: Closing | AI8: Total Units Kwh / d
A9: 45139 | B9: 687120.5 | C9: 688815.9 | D9: =SUM(C9-B9) -> 1695.4 | E9: - | F9: - | G9: - | H9: 196311.84 | I9: 197100 | J9: =SUM(I9-H9) -> 788.16 | K9: 72784.44 | L9: 72943.28 | M9: =SUM(L9-K9) -> 158.84 | N9: 127202.2 | O9: 127673.6 | P9: =SUM(O9-N9-V9) -> 492.76 | Q9: 99732.64 | R9: 100014.8 | S9: =SUM(R9-Q9) -> 282.16 | T9: 17727.52 | U9: 17706.16 | V9: =SUM(U9-T9) -> -21.36 | W9: 52800 | X9: 52959.16 | Y9: =SUM(X9-W9) -> 159.16 | Z9: 29314.8 | AA9: 29415.2 | AB9: =SUM(AA9-Z9) -> 100.4 | AF9: =SUM(AB9+Y9+V9+S9+P9+M9+J9+D9) -> 3655.52 | AG9: 1301320.2 | AH9: 1305284 | AI9: =SUM(AH9-AG9) -> 3963.8 | AJ9: =SUM(AI9-AF9) -> 308.28
A10: 45140 | B10: =C9 -> 688815.9 | C10: 691269.9 | D10: =SUM(C10-B10) -> 2454 | H10: =I9 -> 197100 | I10: 197891.2 | J10: =SUM(I10-H10) -> 791.2 | K10: =L9 -> 72943.28 | L10: 73183.68 | M10: =SUM(L10-K10) -> 240.4 | N10: =O9 -> 127673.6 | O10: 128180.6 | P10: =SUM(O10-N10-V10) -> 127.84 | Q10: =R9 -> 100014.8 | R10: 100313.1 | S10: =SUM(R10-Q10) -> 298.3 | T10: =U9 -> 17706.16 | U10: 18085.32 | V10: =SUM(U10-T10) -> 379.16 | W10: =X9 -> 52959.16 | X10: 53137.85 | Y10: =SUM(X10-W10) -> 178.69 | Z10: =AA9 -> 29415.2 | AA10: 29495.4 | AB10: =SUM(AA10-Z10) -> 80.2 | AF10: =SUM(AB10+Y10+V10+S10+P10+M10+J10+D10) -> 4549.79 | AG10: =AH9 -> 1305284 | AH10: 1310161 | AI10: =SUM(AH10-AG10) -> 4877 | AJ10: =SUM(AI10-AF10) -> 327.21
A11: 45141 | B11: =C10 -> 691269.9 | C11: 694292.9 | D11: =SUM(C11-B11) -> 3023 | H11: =I10 -> 197891.2 | I11: 198596.8 | J11: =SUM(I11-H11) -> 705.6 | K11: =L10 -> 73183.68 | L11: 73618.52 | M11: =SUM(L11-K11) -> 434.84 | N11: =O10 -> 128180.6 | O11: 128705.76 | P11: =SUM(O11-N11-V11) -> 351.72 | Q11: =R10 -> 100313.1 | R11: 100670.2 | S11: =SUM(R11-Q11) -> 357.1 | T11: =U10 -> 18085.32 | U11: 18258.76 | V11: =SUM(U11-T11) -> 173.44 | W11: =X10 -> 53137.85 | X11: 53306.84 | Y11: =SUM(X11-W11) -> 168.99 | Z11: =AA10 -> 29495.4 | AA11: 29583.33 | AB11: =SUM(AA11-Z11) -> 87.93 | AF11: =SUM(AB11+Y11+V11+S11+P11+M11+J11+D11) -> 5302.62 | AG11: =AH10 -> 1310161 | AH11: 1315782.2 | AI11: =SUM(AH11-AG11) -> 5621.17 | AJ11: =SUM(AI11-AF11) -> 318.55
A12: 45142 | B12: =C11 -> 694292.9 | C12: 698438.4 | D12: =SUM(C12-B12) -> 4145.5 | H12: =I11 -> 198596.8 | I12: 199938.6 | J12: =SUM(I12-H12) -> 1341.8 | K12: =L11 -> 73618.52 | L12: 73932.72 | M12: =SUM(L12-K12) -> 314.2 | N12: =O11 -> 128705.76 | O12: 129366 | P12: =SUM(O12-N12-V12) -> 443.68 | Q12: =R11 -> 100670.2 | R12: 101140.64 | S12: =SUM(R12-Q12) -> 470.44 | T12: =U11 -> 18258.76 | U12: 18475.32 | V12: =SUM(U12-T12) -> 216.56 | W12: =X11 -> 53306.84 | X12: 53481.26 | Y12: =SUM(X12-W12) -> 174.42 | Z12: =AA11 -> 29583.33 | AA12: 29686.21 | AB12: =SUM(AA12-Z12) -> 102.88 | AF12: =SUM(AB12+Y12+V12+S12+P12+M12+J12+D12) -> 7209.48 | AG12: =AH11 -> 1315782.2 | AH12: 1323326 | AI12: =SUM(AH12-AG12) -> 7543.83 | AJ12: =SUM(AI12-AF12) -> 334.35
A13: 45143 | B13: =C12 -> 698438.4 | C13: 703357.8 | D13: =SUM(C13-B13) -> 4919.401 | H13: =I12 -> 199938.6 | I13: 201235.84 | J13: =SUM(I13-H13) -> 1297.24 | K13: =L12 -> 73932.72 | L13: 74381.36 | M13: =SUM(L13-K13) -> 448.64 | N13: =O12 -> 129366 | O13: 130146.9 | P13: =SUM(O13-N13-V13) -> 534.97 | Q13: =R12 -> 101140.64 | R13: 101639.92 | S13: =SUM(R13-Q13) -> 499.28 | T13: =U12 -> 18475.32 | U13: 18721.25 | V13: =SUM(U13-T13) -> 245.93 | W13: =X12 -> 53481.26 | X13: 53757.81 | Y13: =SUM(X13-W13) -> 276.55 | Z13: =AA12 -> 29686.21 | AA13: 29789.43 | AB13: =SUM(AA13-Z13) -> 103.22 | AF13: =SUM(AB13+Y13+V13+S13+P13+M13+J13+D13) -> 8325.231 | AG13: =AH12 -> 1323326 | AH13: 1332067.6 | AI13: =SUM(AH13-AG13) -> 8741.6 | AJ13: =SUM(AI13-AF13) -> 416.369
A14: 45144 | B14: =C13 -> 703357.8 | C14: 707623.48 | D14: =SUM(C14-B14) -> 4265.679 | H14: =I13 -> 201235.84 | I14: 202718.16 | J14: =SUM(I14-H14) -> 1482.32 | K14: =L13 -> 74381.36 | L14: 74686.6 | M14: =SUM(L14-K14) -> 305.24 | N14: =O13 -> 130146.9 | O14: 130917.68 | P14: =SUM(O14-N14-V14) -> 525.67 | Q14: =R13 -> 101639.92 | R14: 102104.24 | S14: =SUM(R14-Q14) -> 464.32 | T14: =U13 -> 18721.25 | U14: 18966.36 | V14: =SUM(U14-T14) -> 245.11 | W14: =X13 -> 53757.81 | X14: 54028.72 | Y14: =SUM(X14-W14) -> 270.91 | Z14: =AA13 -> 29789.43 | AA14: 29893.83 | AB14: =SUM(AA14-Z14) -> 104.4 | AF14: =SUM(AB14+Y14+V14+S14+P14+M14+J14+D14) -> 7663.649 | AG14: =AH13 -> 1332067.6 | AH14: 1339998.3 | AI14: =SUM(AH14-AG14) -> 7930.71 | AJ14: =SUM(AI14-AF14) -> 267.061
A15: 45145 | B15: =C14 -> 707623.48 | C15: 711612.9 | D15: =SUM(C15-B15) -> 3989.42 | H15: =I14 -> 202718.16 | I15: 203909.2 | J15: =SUM(I15-H15) -> 1191.04 | K15: =L14 -> 74686.6 | L15: 75012.36 | M15: =SUM(L15-K15) -> 325.76 | N15: =O14 -> 130917.68 | O15: 131671.84 | P15: =SUM(O15-N15-V15) -> 526.32 | Q15: =R14 -> 102104.24 | R15: 102534.1 | S15: =SUM(R15-Q15) -> 429.86 | T15: =U14 -> 18966.36 | U15: 19194.2 | V15: =SUM(U15-T15) -> 227.84 | W15: =X14 -> 54028.72 | X15: 54303.4 | Y15: =SUM(X15-W15) -> 274.68 | Z15: =AA14 -> 29893.83 | AA15: 30006.82 | AB15: =SUM(AA15-Z15) -> 112.99 | AF15: =SUM(AB15+Y15+V15+S15+P15+M15+J15+D15) -> 7077.91 | AG15: =AH14 -> 1339998.3 | AH15: 1347466 | AI15: =SUM(AH15-AG15) -> 7467.69 | AJ15: =SUM(AI15-AF15) -> 389.78
A16: 45146 | B16: =C15 -> 711612.9 | C16: 715690.02 | D16: =SUM(C16-B16) -> 4077.12 | H16: =I15 -> 203909.2 | I16: 205359.76 | J16: =SUM(I16-H16) -> 1450.56 | K16: =L15 -> 75012.36 | L16: 75644.76 | M16: =SUM(L16-K16) -> 632.4 | N16: =O15 -> 131671.84 | O16: 132400.48 | P16: =SUM(O16-N16-V16) -> 506.8 | Q16: =R15 -> 102534.1 | R16: 102986 | S16: =SUM(R16-Q16) -> 451.9 | T16: =U15 -> 19194.2 | U16: 19416.04 | V16: =SUM(U16-T16) -> 221.84 | W16: =X15 -> 54303.4 | X16: 54576.42 | Y16: =SUM(X16-W16) -> 273.02 | Z16: =AA15 -> 30006.82 | AA16: 30128.59 | AB16: =SUM(AA16-Z16) -> 121.77 | AF16: =SUM(AB16+Y16+V16+S16+P16+M16+J16+D16) -> 7735.41 | AG16: =AH15 -> 1347466 | AH16: 1355541.8 | AI16: =SUM(AH16-AG16) -> 8075.75 | AJ16: =SUM(AI16-AF16) -> 340.34
A17: 45147 | B17: =C16 -> 715690.02 | C17: 719714.29 | D17: =SUM(C17-B17) -> 4024.27 | H17: =I16 -> 205359.76 | I17: 206725.6 | J17: =SUM(I17-H17) -> 1365.84 | K17: =L16 -> 75644.76 | L17: 76106.12 | M17: =SUM(L17-K17) -> 461.36 | N17: =O16 -> 132400.48 | O17: 133169.28 | P17: =SUM(O17-N17-V17) -> 535.4 | Q17: =R16 -> 102986 | R17: 103450.64 | S17: =SUM(R17-Q17) -> 464.64 | T17: =U16 -> 19416.04 | U17: 19649.44 | V17: =SUM(U17-T17) -> 233.4 | W17: =X16 -> 54576.42 | X17: 54851.54 | Y17: =SUM(X17-W17) -> 275.12 | Z17: =AA16 -> 30128.59 | AA17: 30278.38 | AB17: =SUM(AA17-Z17) -> 149.79 | AF17: =SUM(AB17+Y17+V17+S17+P17+M17+J17+D17) -> 7509.82 | AG17: =AH16 -> 1355541.8 | AH17: 1363417.2 | AI17: =SUM(AH17-AG17) -> 7875.41 | AJ17: =SUM(AI17-AF17) -> 365.59
A18: 45148 | B18: =C17 -> 719714.29 | C18: 723889.6 | D18: =SUM(C18-B18) -> 4175.31 | E18: 4.08 | F18: 5.42 | G18: =SUM(F18-E18) -> 1.34 | H18: =I17 -> 206725.6 | I18: 208074.56 | J18: =SUM(I18-H18) -> 1348.96 | K18: =L17 -> 76106.12 | L18: 76436 | M18: =SUM(L18-K18) -> 329.88 | N18: =O17 -> 133169.28 | O18: 133895 | P18: =SUM(O18-N18-V18) -> 527.16 | Q18: =R17 -> 103450.64 | R18: 103894.48 | S18: =SUM(R18-Q18) -> 443.84 | T18: =U17 -> 19649.44 | U18: 19848 | V18: =SUM(U18-T18) -> 198.56 | W18: =X17 -> 54851.54 | X18: 55100.58 | Y18: =SUM(X18-W18) -> 249.04 | Z18: =AA17 -> 30278.38 | AA18: 30433.48 | AB18: =SUM(AA18-Z18) -> 155.1 | AF18: =SUM(AB18+Y18+V18+S18+P18+M18+J18+D18+G18) -> 7429.19 | AG18: =AH17 -> 1363417.2 | AH18: 1371236.2 | AI18: =SUM(AH18-AG18) -> 7819.02 | AJ18: =SUM(AI18-AF18) -> 389.83
A19: 45149 | B19: =C18 -> 723889.6 | C19: 727054.2 | D19: =SUM(C19-B19) -> 3164.6 | E19: =F18 -> 5.42 | F19: 6.54 | G19: =SUM(F19-E19) -> 1.12 | H19: =I18 -> 208074.56 | I19: 209023.12 | J19: =SUM(I19-H19) -> 948.56 | K19: =L18 -> 76436 | L19: 76709.8 | M19: =SUM(L19-K19) -> 273.8 | N19: =O18 -> 133895 | O19: 134483.12 | P19: =SUM(O19-N19-V19) -> 417.82 | Q19: =R18 -> 103894.48 | R19: 104343.83 | S19: =SUM(R19-Q19) -> 449.35 | T19: =U18 -> 19848 | U19: 20018.3 | V19: =SUM(U19-T19) -> 170.3 | W19: =X18 -> 55100.58 | X19: 55286.3 | Y19: =SUM(X19-W19) -> 185.72 | Z19: =AA18 -> 30433.48 | AA19: 30556.1 | AB19: =SUM(AA19-Z19) -> 122.62 | AF19: =SUM(AB19+Y19+V19+S19+P19+M19+J19+D19+G19) -> 5733.89 | AG19: =AH18 -> 1371236.2 | AH19: 1377250.9 | AI19: =SUM(AH19-AG19) -> 6014.72 | AJ19: =SUM(AI19-AF19) -> 280.83
A20: 45150 | B20: =C19 -> 727054.2 | C20: 730124.14 | D20: =SUM(C20-B20) -> 3069.94 | E20: =F19 -> 6.54 | F20: 7.48 | G20: =SUM(F20-E20) -> 0.94 | H20: =I19 -> 209023.12 | I20: 210078.96 | J20: =SUM(I20-H20) -> 1055.84 | K20: =L19 -> 76709.8 | L20: 76989.48 | M20: =SUM(L20-K20) -> 279.68 | N20: =O19 -> 134483.12 | O20: 135064.16 | P20: =SUM(O20-N20-V20) -> 392.26 | Q20: =R19 -> 104343.83 | R20: 104708.56 | S20: =SUM(R20-Q20) -> 364.73 | T20: =U19 -> 20018.3 | U20: 20207.08 | V20: =SUM(U20-T20) -> 188.78 | W20: =X19 -> 55286.3 | X20: 55464.63 | Y20: =SUM(X20-W20) -> 178.33 | Z20: =AA19 -> 30556.1 | AA20: 30440.37 | AB20: =SUM(AA20-Z20) -> -115.73 | AF20: =SUM(AB20+Y20+V20+S20+P20+M20+J20+D20+G20) -> 5414.77 | AG20: =AH19 -> 1377250.9 | AH20: 1383087.9 | AI20: =SUM(AH20-AG20) -> 5836.98 | AJ20: =SUM(AI20-AF20) -> 422.21
A21: 45151 | B21: =C20 -> 730124.14 | C21: 732873.43 | D21: =SUM(C21-B21) -> 2749.29 | E21: =F20 -> 7.48 | F21: 7.5 | G21: =SUM(F21-E21) -> 0.02 | H21: =I20 -> 210078.96 | I21: 211078.8 | J21: =SUM(I21-H21) -> 999.84 | K21: =L20 -> 76989.48 | L21: 77187.3 | M21: =SUM(L21-K21) -> 197.82 | N21: =O20 -> 135064.16 | O21: 135590.16 | P21: =SUM(O21-N21-V21) -> 353.88 | Q21: =R20 -> 104708.56 | R21: 105124.72 | S21: =SUM(R21-Q21) -> 416.16 | T21: =U20 -> 20207.08 | U21: 20379.2 | V21: =SUM(U21-T21) -> 172.12 | W21: =X20 -> 55464.63 | X21: 55635.99 | Y21: =SUM(X21-W21) -> 171.36 | Z21: =AA20 -> 30440.37 | AA21: 30763.89 | AB21: =SUM(AA21-Z21) -> 323.52 | AF21: =SUM(AB21+Y21+V21+S21+P21+M21+J21+D21+G21) -> 5384.01 | AG21: =AH20 -> 1383087.9 | AH21: 1388647.9 | AI21: =SUM(AH21-AG21) -> 5560.02 | AJ21: =SUM(AI21-AF21) -> 176.01
A22: 45152 | B22: - | E22: - | G22: - | H22: - | K22: - | M22: - | N22: - | P22: - | Q22: - | S22: - | T22: - | V22: - | W22: - | Y22: - | Z22: - | AB22: - | AF22: - | AG22: - | AI22: - | AJ22: -
A23: 45153 | B23: 732873.43 | C23: 735627.03 | D23: =SUM(C23-B23) -> 2753.6 | E23: 7.5 | F23: 7.51 | G23: =SUM(F23-E23) -> 0.01 | H23: 211078.8 | I23: 212448.96 | J23: =SUM(I23-H23) -> 1370.16 | K23: 77187.3 | L23: 77375.88 | M23: =SUM(L23-K23) -> 188.58 | N23: 135590.16 | O23: 136327.44 | P23: =SUM(O23-N23-V23) -> 504.18 | Q23: 105124.72 | R23: 105462.48 | S23: =SUM(R23-Q23) -> 337.76 | T23: 20379.2 | U23: 20612.3 | V23: =SUM(U23-T23) -> 233.1 | W23: 55635.99 | X23: 55882.71 | Y23: =SUM(X23-W23) -> 246.72 | Z23: 30763.89 | AA23: 30896.14 | AB23: =SUM(AA23-Z23) -> 132.25 | AF23: =SUM(AB23+Y23+V23+S23+P23+M23+J23+D23+G23) -> 5766.36 | AG23: 1388647.9 | AH23: 1394770 | AI23: =SUM(AH23-AG23) -> 6122.08 | AJ23: =SUM(AI23-AF23) -> 355.72
A24: 45154 | B24: 735627.03 | C24: 738475.1 | D24: =SUM(C24-B24) -> 2848.07 | E24: =F23 -> 7.51 | F24: 10.77 | G24: =SUM(F24-E24) -> 3.26 | H24: =I23 -> 212448.96 | I24: 213451.68 | J24: =SUM(I24-H24) -> 1002.72 | K24: =L23 -> 77375.88 | L24: 77646.36 | M24: =SUM(L24-K24) -> 270.48 | N24: =O23 -> 136327.44 | O24: 136904.48 | P24: =SUM(O24-N24-V24) -> 403.54 | Q24: =R23 -> 105462.48 | R24: 105828.1 | S24: =SUM(R24-Q24) -> 365.62 | T24: =U23 -> 20612.3 | U24: 20785.8 | V24: =SUM(U24-T24) -> 173.5 | W24: =X23 -> 55882.71 | X24: 56027.52 | Y24: =SUM(X24-W24) -> 144.81 | Z24: =AA23 -> 30896.14 | AA24: 31021.5 | AB24: =SUM(AA24-Z24) -> 125.36 | AF24: =SUM(AB24+Y24+V24+S24+P24+M24+J24+D24+G24) -> 5337.36 | AG24: =AH23 -> 1394770 | AH24: 1400423.6 | AI24: =SUM(AH24-AG24) -> 5653.62 | AJ24: =SUM(AI24-AF24) -> 316.26
A25: 45155 | B25: =C24 -> 738475.1 | C25: 741546.6 | D25: =SUM(C25-B25) -> 3071.5 | E25: =F24 -> 10.77 | F25: 11.35 | G25: =SUM(F25-E25) -> 0.58 | H25: =I24 -> 213451.68 | I25: 214258.72 | J25: =SUM(I25-H25) -> 807.04 | K25: =L24 -> 77646.36 | L25: 77920.4 | M25: =SUM(L25-K25) -> 274.04 | N25: =O24 -> 136904.48 | O25: 137476.72 | P25: =SUM(O25-N25-V25) -> 388.36 | Q25: =R24 -> 105828.1 | R25: 106220.56 | S25: =SUM(R25-Q25) -> 392.46 | T25: =U24 -> 20785.8 | U25: 20969.68 | V25: =SUM(U25-T25) -> 183.88 | W25: =X24 -> 56027.52 | X25: 56172.47 | Y25: =SUM(X25-W25) -> 144.95 | Z25: =AA24 -> 31021.5 | AA25: 31110.73 | AB25: =SUM(AA25-Z25) -> 89.23 | AF25: =SUM(AB25+Y25+V25+S25+P25+M25+J25+D25+G25) -> 5352.04 | AG25: =AH24 -> 1400423.6 | AH25: 1406108.4 | AI25: =SUM(AH25-AG25) -> 5684.82 | AJ25: =SUM(AI25-AF25) -> 332.78
A26: 45156 | B26: =C25 -> 741546.6 | C26: 744604.16 | D26: =SUM(C26-B26) -> 3057.56 | E26: =F25 -> 11.35 | F26: 12.36 | G26: =SUM(F26-E26) -> 1.01 | H26: =I25 -> 214258.72 | I26: 215429 | J26: =SUM(I26-H26) -> 1170.28 | K26: =L25 -> 77920.4 | L26: 78196.96 | M26: =SUM(L26-K26) -> 276.56 | N26: =O25 -> 137476.72 | O26: 138152.56 | P26: =SUM(O26-N26-V26) -> 458.28 | Q26: =R25 -> 106220.56 | R26: 106625.92 | S26: =SUM(R26-Q26) -> 405.36 | T26: =U25 -> 20969.68 | U26: 21187.24 | V26: =SUM(U26-T26) -> 217.56 | W26: =X25 -> 56172.47 | X26: 56346.01 | Y26: =SUM(X26-W26) -> 173.54 | Z26: =AA25 -> 31110.73 | AA26: 31204.1 | AB26: =SUM(AA26-Z26) -> 93.37 | AF26: =SUM(AB26+Y26+V26+S26+P26+M26+J26+D26+G26) -> 5853.52 | AG26: =AH25 -> 1406108.4 | AH26: 1412287.3 | AI26: =SUM(AH26-AG26) -> 6178.87 | AJ26: =SUM(AI26-AF26) -> 325.35
A27: 45157 | B27: =C26 -> 744604.16 | C27: 747667.9 | D27: =SUM(C27-B27) -> 3063.74 | E27: =F26 -> 12.36 | F27: 17.71 | G27: =SUM(F27-E27) -> 5.35 | H27: =I26 -> 215429 | I27: 216395.28 | J27: =SUM(I27-H27) -> 966.28 | K27: =L26 -> 78196.96 | L27: 78470.2 | M27: =SUM(L27-K27) -> 273.24 | N27: =O26 -> 138152.56 | O27: 138760.32 | P27: =SUM(O27-N27-V27) -> 418.24 | Q27: =R26 -> 106625.92 | R27: 106996.8 | S27: =SUM(R27-Q27) -> 370.88 | T27: =U26 -> 21187.24 | U27: 21376.76 | V27: =SUM(U27-T27) -> 189.52 | W27: =X26 -> 56346.01 | X27: 56490.04 | Y27: =SUM(X27-W27) -> 144.03 | Z27: =AA26 -> 31204.1 | AA27: 31262.03 | AB27: =SUM(AA27-Z27) -> 57.93 | AF27: =SUM(AB27+Y27+V27+S27+P27+M27+J27+D27+G27) -> 5489.21 | AG27: =AH26 -> 1412287.3 | AH27: 1418061.2 | AI27: =SUM(AH27-AG27) -> 5773.91 | AJ27: =SUM(AI27-AF27) -> 284.7
A28: 45158 | B28: =C27 -> 747667.9 | C28: 750966.43 | D28: =SUM(C28-B28) -> 3298.53 | E28: =F27 -> 17.71 | F28: 17.77 | G28: =SUM(F28-E28) -> 0.06 | H28: =I27 -> 216395.28 | I28: 217246.4 | J28: =SUM(I28-H28) -> 851.12 | K28: =L27 -> 78470.2 | L28: 78659.68 | M28: =SUM(L28-K28) -> 189.48 | N28: =O27 -> 138760.32 | O28: 139382.16 | P28: =SUM(O28-N28-V28) -> 446.4 | Q28: =R27 -> 106996.8 | R28: 107390 | S28: =SUM(R28-Q28) -> 393.2 | T28: =U27 -> 21376.76 | U28: 21552.2 | V28: =SUM(U28-T28) -> 175.44 | W28: =X27 -> 56490.04 | X28: 56632.23 | Y28: =SUM(X28-W28) -> 142.19 | Z28: =AA27 -> 31262.03 | AA28: 31335.92 | AB28: =SUM(AA28-Z28) -> 73.89 | AF28: =SUM(AB28+Y28+V28+S28+P28+M28+J28+D28+G28) -> 5570.31 | AG28: =AH27 -> 1418061.2 | AH28: 1423875.3 | AI28: =SUM(AH28-AG28) -> 5814.09 | AJ28: =SUM(AI28-AF28) -> 243.78
A29: 45159 | B29: =C28 -> 750966.43 | C29: 754110.5 | D29: =SUM(C29-B29) -> 3144.07 | E29: =F28 -> 17.77 | F29: 21.77 | G29: =SUM(F29-E29) -> 4 | H29: =I28 -> 217246.4 | I29: 218729.28 | J29: =SUM(I29-H29) -> 1482.88 | K29: =L28 -> 78659.68 | L29: 78956.56 | M29: =SUM(L29-K29) -> 296.88 | N29: =O28 -> 139382.16 | O29: 140101.84 | P29: =SUM(O29-N29-V29) -> 560.52 | Q29: =R28 -> 107390 | R29: 107741.36 | S29: =SUM(R29-Q29) -> 351.36 | T29: =U28 -> 21552.2 | U29: 21711.36 | V29: =SUM(U29-T29) -> 159.16 | W29: =X28 -> 56632.23 | X29: 56880.8 | Y29: =SUM(X29-W29) -> 248.57 | Z29: =AA28 -> 31335.92 | AA29: 31412.4 | AB29: =SUM(AA29-Z29) -> 76.48 | AF29: =SUM(AB29+Y29+V29+S29+P29+M29+J29+D29+G29) -> 6323.92 | AG29: =AH28 -> 1423875.3 | AH29: 1430581.6 | AI29: =SUM(AH29-AG29) -> 6706.31 | AJ29: =SUM(AI29-AF29) -> 382.39
A30: 45160 | B30: =C29 -> 754110.5 | C30: 755913.99 | D30: =SUM(C30-B30) -> 1803.49 | E30: =F29 -> 21.77 | F30: 21.74 | G30: =SUM(F30-E30) -> -0.03 | H30: =I29 -> 218729.28 | I30: 219707.76 | J30: =SUM(I30-H30) -> 978.48 | K30: =L29 -> 78956.56 | L30: 79253.2 | M30: =SUM(L30-K30) -> 296.64 | N30: =O29 -> 140101.84 | O30: 140577.68 | P30: =SUM(O30-N30-V30) -> 339.88 | Q30: =R29 -> 107741.36 | R30: 107974 | S30: =SUM(R30-Q30) -> 232.64 | T30: =U29 -> 21711.36 | U30: 21847.32 | V30: =SUM(U30-T30) -> 135.96 | W30: =X29 -> 56880.8 | X30: 57048.63 | Y30: =SUM(X30-W30) -> 167.83 | Z30: =AA29 -> 31412.4 | AA30: 31491.88 | AB30: =SUM(AA30-Z30) -> 79.48 | AF30: =SUM(AB30+Y30+V30+S30+P30+M30+J30+D30+G30) -> 4034.37 | AG30: =AH29 -> 1430581.6 | AH30: 1434900.3 | AI30: =SUM(AH30-AG30) -> 4318.7 | AJ30: =SUM(AI30-AF30) -> 284.33
A31: 45161 | B31: =C30 -> 755913.99 | C31: 758968.9 | D31: =SUM(C31-B31) -> 3054.91 | E31: =F30 -> 21.74 | F31: 23.2 | G31: =SUM(F31-E31) -> 1.46 | H31: =I30 -> 219707.76 | I31: 220507.9 | J31: =SUM(I31-H31) -> 800.14 | K31: =L30 -> 79253.2 | L31: 79486.94 | M31: =SUM(L31-K31) -> 233.74 | N31: =O30 -> 140577.68 | O31: 141151.84 | P31: =SUM(O31-N31-V31) -> 393.6 | Q31: =R30 -> 107974 | R31: 108341.6 | S31: =SUM(R31-Q31) -> 367.6 | T31: =U30 -> 21847.32 | U31: 22027.88 | V31: =SUM(U31-T31) -> 180.56 | W31: =X30 -> 57048.63 | X31: 57201.35 | Y31: =SUM(X31-W31) -> 152.72 | Z31: =AA30 -> 31491.88 | AA31: 31569.4 | AB31: =SUM(AA31-Z31) -> 77.52 | AF31: =SUM(AB31+Y31+V31+S31+P31+M31+J31+D31+G31) -> 5262.25 | AG31: =AH30 -> 1434900.3 | AH31: 1440478 | AI31: =SUM(AH31-AG31) -> 5577.7 | AJ31: =SUM(AI31-AF31) -> 315.45
A32: 45162 | B32: =C31 -> 758968.9 | C32: 761812.91 | D32: =SUM(C32-B32) -> 2844.01 | E32: =F31 -> 23.2 | F32: 24.08 | G32: =SUM(F32-E32) -> 0.88 | H32: =I31 -> 220507.9 | I32: 221305.26 | J32: =SUM(I32-H32) -> 797.36 | K32: =L31 -> 79486.94 | L32: 80007.08 | M32: =SUM(L32-K32) -> 520.14 | N32: =O31 -> 141151.84 | O32: 141711.52 | P32: =SUM(O32-N32-V32) -> 373.48 | Q32: =R31 -> 108341.6 | R32: 108740.72 | S32: =SUM(R32-Q32) -> 399.12 | T32: =U31 -> 22027.88 | U32: 22214.08 | V32: =SUM(U32-T32) -> 186.2 | W32: =X31 -> 57201.35 | X32: 57343.22 | Y32: =SUM(X32-W32) -> 141.87 | Z32: =AA31 -> 31569.4 | AA32: 31660.01 | AB32: =SUM(AA32-Z32) -> 90.61 | AF32: =SUM(AB32+Y32+V32+S32+P32+M32+J32+D32+G32) -> 5353.67 | AG32: =AH31 -> 1440478 | AH32: 1446106.5 | AI32: =SUM(AH32-AG32) -> 5628.5 | AJ32: =SUM(AI32-AF32) -> 274.83
A33: 45163 | B33: =C32 -> 761812.91 | C33: 764600 | D33: =SUM(C33-B33) -> 2787.09 | E33: =F32 -> 24.08 | F33: 24.96 | G33: =SUM(F33-E33) -> 0.88 | H33: =I32 -> 221305.26 | I33: 222381.48 | J33: =SUM(I33-H33) -> 1076.22 | K33: =L32 -> 80007.08 | L33: 80214.16 | M33: =SUM(L33-K33) -> 207.08 | N33: =O32 -> 141711.52 | O33: 142260.1 | P33: =SUM(O33-N33-V33) -> 372.46 | Q33: =R32 -> 108740.72 | R33: 109053.68 | S33: =SUM(R33-Q33) -> 312.96 | T33: =U32 -> 22214.08 | U33: 22390.2 | V33: =SUM(U33-T33) -> 176.12 | W33: =X32 -> 57343.22 | X33: 57512.48 | Y33: =SUM(X33-W33) -> 169.26 | Z33: =AA32 -> 31660.01 | AA33: 31727.85 | AB33: =SUM(AA33-Z33) -> 67.84 | AF33: =SUM(AB33+Y33+V33+S33+P33+M33+J33+D33+G33) -> 5169.91 | AG33: =AH32 -> 1446106.5 | AH33: 1451483 | AI33: =SUM(AH33-AG33) -> 5376.5 | AJ33: =SUM(AI33-AF33) -> 206.59
A34: 45164 | B34: =C33 -> 764600 | C34: 767559.23 | D34: =SUM(C34-B34) -> 2959.23 | E34: =F33 -> 24.96 | F34: 25.92 | G34: =SUM(F34-E34) -> 0.96 | H34: =I33 -> 222381.48 | I34: 223386.08 | J34: =SUM(I34-H34) -> 1004.6 | K34: =L33 -> 80214.16 | L34: 80437.84 | M34: =SUM(L34-K34) -> 223.68 | N34: =O33 -> 142260.1 | O34: 142797.4 | P34: =SUM(O34-N34-V34) -> 362.5 | Q34: =R33 -> 109053.68 | R34: 109408.6 | S34: =SUM(R34-Q34) -> 354.92 | T34: =U33 -> 22390.2 | U34: 22565 | V34: =SUM(U34-T34) -> 174.8 | W34: =X33 -> 57512.48 | X34: 57685.09 | Y34: =SUM(X34-W34) -> 172.61 | Z34: =AA33 -> 31727.85 | AA34: 31836.38 | AB34: =SUM(AA34-Z34) -> 108.53 | AF34: =SUM(AB34+Y34+V34+S34+P34+M34+J34+D34+G34) -> 5361.83 | AG34: =AH33 -> 1451483 | AH34: 1457186.4 | AI34: =SUM(AH34-AG34) -> 5703.4 | AJ34: =SUM(AI34-AF34) -> 341.57
A35: 45165 | B35: =C34 -> 767559.23 | C35: 770812.38 | D35: =SUM(C35-B35) -> 3253.15 | E35: =F34 -> 25.92 | F35: 26.75 | G35: =SUM(F35-E35) -> 0.83 | H35: =I34 -> 223386.08 | I35: 224513.84 | J35: =SUM(I35-H35) -> 1127.76 | K35: =L34 -> 80437.84 | L35: 80747.56 | M35: =SUM(L35-K35) -> 309.72 | N35: =O34 -> 142797.4 | O35: 143350.2 | P35: =SUM(O35-N35-V35) -> 383.88 | Q35: =R34 -> 109408.6 | R35: 109786.4 | S35: =SUM(R35-Q35) -> 377.8 | T35: =U34 -> 22565 | U35: 22733.92 | V35: =SUM(U35-T35) -> 168.92 | W35: =X34 -> 57685.09 | X35: 57831.45 | Y35: =SUM(X35-W35) -> 146.36 | Z35: =AA34 -> 31836.38 | AA35: 31907.75 | AB35: =SUM(AA35-Z35) -> 71.37 | AF35: =SUM(AB35+Y35+V35+S35+P35+M35+J35+D35+G35) -> 5839.79 | AG35: =AH34 -> 1457186.4 | AH35: 1463253.9 | AI35: =SUM(AH35-AG35) -> 6067.5 | AJ35: =SUM(AI35-AF35) -> 227.71
A36: 45166 | B36: =C35 -> 770812.38 | C36: 775708.1 | D36: =SUM(C36-B36) -> 4895.72 | E36: =F35 -> 26.75 | F36: 27.61 | G36: =SUM(F36-E36) -> 0.86 | H36: =I35 -> 224513.84 | I36: 226221.6 | J36: =SUM(I36-H36) -> 1707.76 | K36: =L35 -> 80747.56 | L36: 81118.32 | M36: =SUM(L36-K36) -> 370.76 | N36: =O35 -> 143350.2 | O36: 144186.16 | P36: =SUM(O36-N36-V36) -> 590.48 | Q36: =R35 -> 109786.4 | R36: 110330.96 | S36: =SUM(R36-Q36) -> 544.56 | T36: =U35 -> 22733.92 | U36: 22979.4 | V36: =SUM(U36-T36) -> 245.48 | W36: =X35 -> 57831.45 | X36: 58004 | Y36: =SUM(X36-W36) -> 172.55 | Z36: =AA35 -> 31907.75 | AA36: 32016.1 | AB36: =SUM(AA36-Z36) -> 108.35 | AF36: =SUM(AB36+Y36+V36+S36+P36+M36+J36+D36+G36) -> 8636.52 | AG36: =AH35 -> 1463253.9 | AH36: 1472323 | AI36: =SUM(AH36-AG36) -> 9069.1 | AJ36: =SUM(AI36-AF36) -> 432.58
A37: 45167 | B37: =C36 -> 775708.1 | C37: 779805.19 | D37: =SUM(C37-B37) -> 4097.09 | E37: =F36 -> 27.61 | F37: 28.47 | G37: =SUM(F37-E37) -> 0.86 | H37: =I36 -> 226221.6 | I37: 227889.2 | J37: =SUM(I37-H37) -> 1667.6 | K37: =L36 -> 81118.32 | L37: 81405.64 | M37: =SUM(L37-K37) -> 287.32 | N37: =O36 -> 144186.16 | O37: 144979.92 | P37: =SUM(O37-N37-V37) -> 556.6 | Q37: =R36 -> 110330.96 | R37: 110831.6 | S37: =SUM(R37-Q37) -> 500.64 | T37: =U36 -> 22979.4 | U37: 23216.56 | V37: =SUM(U37-T37) -> 237.16 | W37: 58004 | X37: 58229.57 | Y37: =SUM(X37-W37) -> 225.57 | Z37: =AA36 -> 32016.1 | AA37: 32118.82 | AB37: =SUM(AA37-Z37) -> 102.72 | AC37: 227.433 | AD37: 587.283 | AE37: =SUM(AD37-AC37) -> 359.85 | AF37: =SUM(AB37+Y37+V37+S37+P37+M37+J37+D37+G37+360) -> 8035.56 | AG37: =AH36 -> 1472323 | AH37: 1480361.4 | AI37: =SUM(AH37-AG37) -> 8038.4 | AJ37: =SUM(AI37-AF37) -> 2.84
A38: 45168 | B38: =C37 -> 779805.19 | C38: 784472 | D38: =SUM(C38-B38) -> 4666.81 | E38: =F37 -> 28.47 | F38: 29.31 | G38: =SUM(F38-E38) -> 0.84 | H38: =I37 -> 227889.2 | I38: 229568.5 | J38: =SUM(I38-H38) -> 1679.3 | K38: =L37 -> 81405.64 | L38: 81723.76 | M38: =SUM(L38-K38) -> 318.12 | N38: =O37 -> 144979.92 | O38: 145830.48 | P38: =SUM(O38-N38-V38) -> 595.84 | Q38: =R37 -> 110831.6 | R38: 111364 | S38: =SUM(R38-Q38) -> 532.4 | T38: =U37 -> 23216.56 | U38: 23471.28 | V38: =SUM(U38-T38) -> 254.72 | W38: =X37 -> 58229.57 | X38: 58428.6 | Y38: =SUM(X38-W38) -> 199.03 | Z38: =AA37 -> 32118.82 | AA38: 32212.6 | AB38: =SUM(AA38-Z38) -> 93.78 | AC38: =AD37 -> 587.283 | AD38: 990.4 | AE38: =SUM(AD38-AC38) -> 403.117 | AF38: =SUM(AB38+Y38+V38+S38+P38+M38+J38+D38+G38+403) -> 8743.84 | AG38: =AH37 -> 1480361.4 | AH38: 1489108.9 | AI38: =SUM(AH38-AG38) -> 8747.5 | AJ38: =SUM(AI38-AF38) -> 3.66
A39: 45169 | B39: =C38 -> 784472 | C39: 789301.92 | D39: =SUM(C39-B39) -> 4829.92 | E39: =F38 -> 29.31 | F39: 31.35 | G39: =SUM(F39-E39) -> 2.04 | H39: =I38 -> 229568.5 | I39: 231264.69 | J39: =SUM(I39-H39) -> 1696.19 | K39: =L38 -> 81723.76 | L39: 82274.76 | M39: =SUM(L39-K39) -> 551 | N39: =O38 -> 145830.48 | O39: 146672.8 | P39: =SUM(O39-N39-V39) -> 592.84 | Q39: =R38 -> 111364 | R39: 111884.64 | S39: =SUM(R39-Q39) -> 520.64 | T39: =U38 -> 23471.28 | U39: 23720.76 | V39: =SUM(U39-T39) -> 249.48 | W39: =X38 -> 58428.6 | X39: 58638.5 | Y39: =SUM(X39-W39) -> 209.9 | Z39: =AA38 -> 32212.6 | AA39: 32343.8 | AB39: =SUM(AA39-Z39) -> 131.2 | AC39: =AD38 -> 990.4 | AD39: 1398 | AE39: =SUM(AD39-AC39) -> 407.6 | AF39: =SUM(AB39+Y39+V39+S39+P39+M39+J39+D39+G39+408) -> 9191.21 | AG39: =AH38 -> 1489108.9 | AH39: 1498305.8 | AI39: =SUM(AH39-AG39) -> 9196.9 | AJ39: =SUM(AI39-AF39) -> 5.69
D40: =SUM(D8:D39) -> 102181.42 | G40: =SUM(G9:G39) -> 27.27 | J40: =SUM(J9:J39) -> 34952.85 | M40: =SUM(M9:M39) -> 9490.32 | P40: =SUM(P9:P39) -> 13477.36 | S40: =SUM(S9:S39) -> 12152 | V40: =SUM(V9:V39) -> 5993.24 | Y40: =SUM(Y9:Y39) -> 5838.5 | AB40: =SUM(AB9:AB39) -> 3029 | AE40: =SUM(AE9:AE39) -> 1170.567 | AI40: =SUM(AI9:AI39) -> 196985.6

Sheet Sep 2023
A2: FOR THE MONTH OF SEPTEMBER 2023
A4: DATE | B4: KWH REPORT FIBER BLEACHING
B6: BUSWAY 1 (PRE AND POST BLOW ROOM + DRYER +BLEACHING MACHINES+ STAMP PRESS+ CAKE OPENOR+ CENTRIFUGE+ BALE PRESS) | E6: BUSWAY 2 | H6: MCC 1 (EXHAUST FAN+ FA FAN+ DRYER FAN+ SUBMERSIBLE PUMP +RECYCLE PUMP) | K6: MCC 2 (FA FAN +EXHAUST FAN CHEMICAL AREA+CAUSTIC FEED PUMP+WASTE WATER PUMP) | N6: MCC 3 (COMPRESSOR +FA FAN+ EXHAUST FAN)+BOILER | Q6: MCC 4 (SOFTENING PUMP+UV PUMP+FEED PUMP+ CAUSTIC PUMP+RAW WATER PUMP+ CHEMICAL AREA) | T6: MCC 5 (BOILER) | W6: LPDB 1 (PHASE 1 AND 2 LIGHTENING LOAD) | Z6: LPDB 2 (PRE BLOW ROOM LIGHTENING LOAD) | AC6: LPDB OFFICE
B7: Opening | C7: Closing | D7: Total Units Kwh / d | E7: Opening | F7: Closing | G7: Total Units Kwh / d | H7: Opening | I7: Closing | J7: Total Units Kwh / d | K7: Opening | L7: Closing | M7: Total Units Kwh / d | N7: Opening | O7: Closing | P7: Total Units Kwh / d | Q7: Opening | R7: Closing | S7: Total Units Kwh / d | T7: Opening | U7: Closing | V7: Total Units Kwh / d | W7: Opening | X7: Closing | Y7: Total Units Kwh / d | Z7: Opening | AA7: Closing | AB7: Total Units Kwh / d | AC7: Opening | AD7: Closing | AE7: Total Units Kwh / d | AF7: TOTAL CONSUMED | AG7: MAIN INCOMING | AJ7: Dif b/t main LT and consum
AG8: Opening | AH8: Closing | AI8: Total Units Kwh / d
A9: 45170 | B9: 789301.92 | C9: 793694.92 | D9: =SUM(C9-B9) -> 4393 | E9: 31.35 | F9: 32.19 | G9: =SUM(F9-E9) -> 0.84 | H9: 231264.69 | I9: 232756.4 | J9: =SUM(I9-H9) -> 1491.71 | K9: 82274.76 | L9: 82945.12 | M9: =SUM(L9-K9) -> 670.36 | N9: 146672.8 | O9: 147390.32 | P9: =SUM(O9-N9-V9) -> 489.8 | Q9: 111884.64 | R9: 112346.32 | S9: =SUM(R9-Q9) -> 461.68 | T9: 23720.76 | U9: 23948.48 | V9: =SUM(U9-T9) -> 227.72 | W9: 58638.5 | X9: 58812.71 | Y9: =SUM(X9-W9) -> 174.21 | Z9: 32343.8 | AA9: 32466.9 | AB9: =SUM(AA9-Z9) -> 123.1 | AC9: 1398 | AD9: 1690 | AE9: =SUM(AD9-AC9) -> 292 | AF9: =SUM(AB9+Y9+V9+S9+P9+M9+J9+D9+AE9) -> 8323.58 | AG9: 1498305.8 | AH9: 1506633.5 | AI9: =SUM(AH9-AG9) -> 8327.72 | AJ9: =SUM(AI9-AF9) -> 4.14
A10: 45171 | B10: =C9 -> 793694.92 | C10: 798264.3 | D10: =SUM(C10-B10) -> 4569.38 | E10: =F9 -> 32.19 | F10: 33.04 | G10: =SUM(F10-E10) -> 0.85 | H10: =I9 -> 232756.4 | I10: 234263.68 | J10: =SUM(I10-H10) -> 1507.28 | K10: =L9 -> 82945.12 | L10: 83447.88 | M10: =SUM(L10-K10) -> 502.76 | N10: =O9 -> 147390.32 | O10: 148137.2 | P10: =SUM(O10-N10-V10) -> 502.72 | Q10: =R9 -> 112346.32 | R10: 112881.92 | S10: =SUM(R10-Q10) -> 535.6 | T10: =U9 -> 23948.48 | U10: 24192.64 | V10: =SUM(U10-T10) -> 244.16 | W10: =X9 -> 58812.71 | X10: 58973.49 | Y10: =SUM(X10-W10) -> 160.78 | Z10: =AA9 -> 32466.9 | AA10: 32594.8 | AB10: =SUM(AA10-Z10) -> 127.9 | AC10: =AD9 -> 1690 | AD10: 1990 | AE10: =SUM(AD10-AC10) -> 300 | AF10: =SUM(AB10+Y10+V10+S10+P10+M10+J10+D10+AE10) -> 8450.58 | AG10: =AH9 -> 1506633.5 | AH10: 1515129.2 | AI10: =SUM(AH10-AG10) -> 8495.68 | AJ10: =SUM(AI10-AF10) -> 45.1
A11: 45172 | B11: =C10 -> 798264.3 | C11: 802312.8 | D11: =SUM(C11-B11) -> 4048.5 | E11: =F10 -> 33.04 | F11: 34.19 | G11: =SUM(F11-E11) -> 1.15 | H11: =I10 -> 234263.68 | I11: 235933.6 | J11: =SUM(I11-H11) -> 1669.92 | K11: =L10 -> 83447.88 | L11: 83913.36 | M11: =SUM(L11-K11) -> 465.48 | N11: =O10 -> 148137.2 | O11: 148852.56 | P11: =SUM(O11-N11-V11) -> 500.68 | Q11: =R10 -> 112881.92 | R11: 113296.96 | S11: =SUM(R11-Q11) -> 415.04 | T11: =U10 -> 24192.64 | U11: 24407.32 | V11: =SUM(U11-T11) -> 214.68 | W11: =X10 -> 58973.49 | X11: 59157.5 | Y11: =SUM(X11-W11) -> 184.01 | Z11: =AA10 -> 32594.8 | AA11: 32715.53 | AB11: =SUM(AA11-Z11) -> 120.73 | AC11: =AD10 -> 1990 | AD11: 2212 | AE11: =SUM(AD11-AC11) -> 222 | AF11: =SUM(AB11+Y11+V11+S11+P11+M11+J11+D11+AE11) -> 7841.04 | AG11: =AH10 -> 1515129.2 | AH11: 1523003.8 | AI11: =SUM(AH11-AG11) -> 7874.6 | AJ11: =SUM(AI11-AF11) -> 33.56
A12: 45173 | B12: =C11 -> 802312.8 | C12: 807593.9 | D12: =SUM(C12-B12) -> 5281.1 | E12: =F11 -> 34.19 | F12: 35.36 | G12: =SUM(F12-E12) -> 1.17 | H12: =I11 -> 235933.6 | I12: 237601 | J12: =SUM(I12-H12) -> 1667.4 | K12: 83913.36 | L12: 84640.72 | M12: =SUM(L12-K12) -> 727.36 | N12: =O11 -> 148852.56 | O12: 149600.8 | P12: =SUM(O12-N12-V12) -> 500.76 | Q12: =R11 -> 113296.96 | R12: 113811.84 | S12: =SUM(R12-Q12) -> 514.88 | T12: =U11 -> 24407.32 | U12: 24654.8 | V12: =SUM(U12-T12) -> 247.48 | W12: =X11 -> 59157.5 | X12: 59408.2 | Y12: =SUM(X12-W12) -> 250.7 | Z12: =AA11 -> 32715.53 | AA12: 32844.13 | AB12: =SUM(AA12-Z12) -> 128.6 | AC12: =AD11 -> 2212 | AD12: 2538 | AE12: =SUM(AD12-AC12) -> 326 | AF12: =SUM(AB12+Y12+V12+S12+P12+M12+J12+D12+AE12) -> 9644.28 | AG12: =AH11 -> 1523003.8 | AH12: 1532758 | AI12: =SUM(AH12-AG12) -> 9754.2 | AJ12: =SUM(AI12-AF12) -> 109.92
A13: 45174 | B13: =C12 -> 807593.9 | C13: 812671.99 | D13: =SUM(C13-B13) -> 5078.09 | E13: =F12 -> 35.36 | F13: 52.41 | G13: =SUM(F13-E13) -> 17.05 | H13: =I12 -> 237601 | I13: 239280.72 | J13: =SUM(I13-H13) -> 1679.72 | K13: =L12 -> 84640.72 | L13: 85334.52 | M13: =SUM(L13-K13) -> 693.8 | N13: =O12 -> 149600.8 | O13: 150408.4 | P13: =SUM(O13-N13-V13) -> 544 | Q13: =R12 -> 113811.84 | R13: 114309.1 | S13: =SUM(R13-Q13) -> 497.26 | T13: =U12 -> 24654.8 | U13: 24918.4 | V13: =SUM(U13-T13) -> 263.6 | W13: =X12 -> 59408.2 | X13: 59647.96 | Y13: =SUM(X13-W13) -> 239.76 | Z13: =AA12 -> 32844.13 | AA13: 32968.52 | AB13: =SUM(AA13-Z13) -> 124.39 | AC13: =AD12 -> 2538 | AD13: 2916 | AE13: =SUM(AD13-AC13) -> 378 | AF13: =SUM(AB13+Y13+V13+S13+P13+M13+J13+D13+AE13) -> 9498.62 | AG13: =AH12 -> 1532758 | AH13: 1542311.3 | AI13: =SUM(AH13-AG13) -> 9553.27 | AJ13: =SUM(AI13-AF13) -> 54.65
A14: 45175 | B14: =C13 -> 812671.99 | C14: 817712.19 | D14: =SUM(C14-B14) -> 5040.2 | E14: =F13 -> 52.41 | F14: 77.95 | G14: =SUM(F14-E14) -> 25.54 | H14: =I13 -> 239280.72 | I14: 240872.08 | J14: =SUM(I14-H14) -> 1591.36 | K14: =L13 -> 85334.52 | L14: 85788.52 | M14: =SUM(L14-K14) -> 454 | N14: =O13 -> 150408.4 | O14: 151248.4 | P14: =SUM(O14-N14-V14) -> 573.92 | Q14: =R13 -> 114309.1 | R14: 114786.48 | S14: =SUM(R14-Q14) -> 477.38 | T14: =U13 -> 24918.4 | U14: 25184.48 | V14: =SUM(U14-T14) -> 266.08 | W14: =X13 -> 59647.96 | X14: 59909.87 | Y14: =SUM(X14-W14) -> 261.91 | Z14: =AA13 -> 32968.52 | AA14: 33109.56 | AB14: =SUM(AA14-Z14) -> 141.04 | AC14: =AD13 -> 2916 | AD14: 3244 | AE14: =SUM(AD14-AC14) -> 328 | AF14: =SUM(AB14+Y14+V14+S14+P14+M14+J14+D14+AE14) -> 9133.89 | AG14: =AH13 -> 1542311.3 | AH14: 1551503.9 | AI14: =SUM(AH14-AG14) -> 9192.59 | AJ14: =SUM(AI14-AF14) -> 58.7
A15: 45176 | B15: =C14 -> 817712.19 | C15: 822654.63 | D15: =SUM(C15-B15) -> 4942.44 | E15: =F14 -> 77.95 | F15: 103.89 | G15: =SUM(F15-E15) -> 25.94 | H15: =I14 -> 240872.08 | I15: 242550.72 | J15: =SUM(I15-H15) -> 1678.64 | K15: =L14 -> 85788.52 | L15: 86688.44 | M15: =SUM(L15-K15) -> 899.92 | N15: =O14 -> 151248.4 | O15: 152065.6 | P15: =SUM(O15-N15-V15) -> 563.16 | Q15: 114786.48 | R15: 115284.72 | S15: =SUM(R15-Q15) -> 498.24 | T15: =U14 -> 25184.48 | U15: 25438.52 | V15: =SUM(U15-T15) -> 254.04 | W15: =X14 -> 59909.87 | X15: 60160.75 | Y15: =SUM(X15-W15) -> 250.88 | Z15: =AA14 -> 33109.56 | AA15: 33235.91 | AB15: =SUM(AA15-Z15) -> 126.35 | AC15: =AD14 -> 3244 | AD15: 3623 | AE15: =SUM(AD15-AC15) -> 379 | AF15: =SUM(AB15+Y15+V15+S15+P15+M15+J15+D15+AE15) -> 9592.67 | AG15: =AH14 -> 1551503.9 | AH15: 1561160.7 | AI15: =SUM(AH15-AG15) -> 9656.87 | AJ15: =SUM(AI15-AF15) -> 64.2
A16: 45177 | B16: =C15 -> 822654.63 | C16: 827629.49 | D16: =SUM(C16-B16) -> 4974.86 | E16: =F15 -> 103.89 | F16: 131.27 | G16: =SUM(F16-E16) -> 27.38 | H16: =I15 -> 242550.72 | I16: 244234.64 | J16: =SUM(I16-H16) -> 1683.92 | K16: =L15 -> 86688.44 | L16: 87375.64 | M16: =SUM(L16-K16) -> 687.2 | N16: =O15 -> 152065.6 | O16: 152896.08 | P16: =SUM(O16-N16-V16) -> 572.24 | Q16: =R15 -> 115284.72 | R16: 115774.96 | S16: =SUM(R16-Q16) -> 490.24 | T16: =U15 -> 25438.52 | U16: 25696.76 | V16: =SUM(U16-T16) -> 258.24 | W16: =X15 -> 60160.75 | X16: 60422.16 | Y16: =SUM(X16-W16) -> 261.41 | Z16: =AA15 -> 33235.91 | AA16: 33361.78 | AB16: =SUM(AA16-Z16) -> 125.87 | AC16: =AD15 -> 3623 | AD16: 3980 | AE16: =SUM(AD16-AC16) -> 357 | AF16: =SUM(AB16+Y16+V16+S16+P16+M16+J16+D16+AE16) -> 9410.98 | AG16: =AH15 -> 1561160.7 | AH16: 1570632.7 | AI16: =SUM(AH16-AG16) -> 9471.97 | AJ16: =SUM(AI16-AF16) -> 60.99
A17: 45178 | B17: =C16 -> 827629.49 | C17: 832696.09 | D17: =SUM(C17-B17) -> 5066.6 | E17: =F16 -> 131.27 | F17: 156.99 | G17: =SUM(F17-E17) -> 25.72 | H17: =I16 -> 244234.64 | I17: 245746.32 | J17: =SUM(I17-H17) -> 1511.68 | K17: =L16 -> 87375.64 | L17: 87909.08 | M17: =SUM(L17-K17) -> 533.44 | N17: =O16 -> 152896.08 | O17: 153611.68 | P17: =SUM(O17-N17-V17) -> 467.48 | Q17: =R16 -> 115774.96 | R17: 116264.56 | S17: =SUM(R17-Q17) -> 489.6 | T17: =U16 -> 25696.76 | U17: 25944.88 | V17: =SUM(U17-T17) -> 248.12 | W17: =X16 -> 60422.16 | X17: 60683.5 | Y17: =SUM(X17-W17) -> 261.34 | Z17: =AA16 -> 33361.78 | AA17: 33486.48 | AB17: =SUM(AA17-Z17) -> 124.7 | AC17: =AD16 -> 3980 | AD17: 4340 | AE17: =SUM(AD17-AC17) -> 360 | AF17: =SUM(AB17+Y17+V17+S17+P17+M17+J17+D17+AE17) -> 9062.96 | AG17: =AH16 -> 1570632.7 | AH17: 1579842.1 | AI17: =SUM(AH17-AG17) -> 9209.39 | AJ17: =SUM(AI17-AF17) -> 146.43
A18: 45179 | B18: =C17 -> 832696.09 | C18: 837655.14 | D18: =SUM(C18-B18) -> 4959.05 | E18: =F17 -> 156.99 | F18: 182.46 | G18: =SUM(F18-E18) -> 25.47 | H18: =I17 -> 245746.32 | I18: 247260.71 | J18: =SUM(I18-H18) -> 1514.39 | K18: =L17 -> 87909.08 | L18: 88443.083 | M18: =SUM(L18-K18) -> 534.003 | N18: =O17 -> 153611.68 | O18: 154591.62 | P18: 690 | Q18: =R17 -> 116264.56 | R18: 116728.56 | S18: =SUM(R18-Q18) -> 464 | T18: =U17 -> 25944.88 | U18: 26190.52 | V18: =SUM(U18-T18) -> 245.64 | W18: =X17 -> 60683.5 | X18: 60945.28 | Y18: =SUM(X18-W18) -> 261.78 | Z18: =AA17 -> 33486.48 | AA18: 33612.4 | AB18: =SUM(AA18-Z18) -> 125.92 | AC18: =AD17 -> 4340 | AD18: 4628 | AE18: =SUM(AD18-AC18) -> 288 | AF18: =SUM(AB18+Y18+V18+S18+P18+M18+J18+D18+AE18) -> 9082.783 | AG18: =AH17 -> 1579842.1 | AH18: 1588932.2 | AI18: =SUM(AH18-AG18) -> 9090.16 | AJ18: =SUM(AI18-AF18) -> 7.377
